Workbook

Sheet Income_Statement
A1: Metric | B1: FY2023 | C1: FY2024 | D1: FY2025
A2: Revenue | B2: 383285 | C2: 391035 | D2: 416161
A3: Cost of Revenue | B3: 214137 | C3: 210352 | D3: 220960
A4: Gross Profit | B4: 169148 | C4: 180683 | D4: 195201
A5: Research & Development (R&D) | B5: 29915 | C5: 31370 | D5: 32086
A6: Selling, General & Administrative (SG&A) | B6: 24932 | C6: 26097 | D6: 27322
A7: Total Operating Expenses | B7: 54847 | C7: 57467 | D7: 59408
A8: Operating Income | B8: 114301 | C8: 123216 | D8: 135793
A9: Interest Expense | B9: 3933 | C9: 3933 | D9: 3933
A10: Interest Income | B10: 3750 | C10: 3750 | D10: 3750
A11: Other Income/(Expense), net | B11: -565 | C11: 382 | D11: 1050
A12: Income Before Tax | B12: 113553 | C12: 123517 | D12: 136660
A13: Provision for Income Taxes | B13: 16741 | C13: 29781 | D13: 24650
... A16: Diluted EPS ($) | B16: 6.16 | C16: 6.16 | D16: 7.46

Sheet Balance_Sheet
A1: Metric | B1: FY2023 | C1: FY2024 | D1: FY2025
A2: Cash and Cash Equivalents | B2: 29965 | C2: 29943 | D2: 35934
A3: Short-term Investments | B3: 31590 | C3: 35228 | D3: 38150
A4: Accounts Receivable | B4: 29508 | C4: 32972 | D4: 34666
A5: Inventories | B5: 6331 | C5: 6511 | D5: 7286
A6: Other Current Assets | B6: 14695 | C6: 16333 | D6: 17921
A7: Total Current Assets | B7: 143566 | C7: 152987 | D7: 147957
A8: Property, Plant & Equipment (net) | B8: 43715 | C8: 44111 | D8: 45688
A9: Long-term Investments | B9: 100544 | C9: 100544 | D9: 100544
A10: Goodwill | B10: 0 | C10: 0 | D10: 0
A11: Intangible Assets | B11: 0 | C11: 0 | D11: 0
A12: Other Long-term Assets | B12: 64758 | C12: 67338 | D12: 65052
A13: Total Non-Current Assets | B13: 209017 | C13: 212003 | D13: 211284
... A28: Total Liabilities and Equity | B28: 352583 | C28: 364980 | D28: 359241

Sheet Cash_Flow
A1: Metric | B1: FY2023 | C1: FY2024 | D1: FY2025
A2: Net Income | B2: 96995 | C2: 93736 | D2: 112010
A3: Depreciation & Amortization | B3: 11519 | C3: 11445 | D3: 11619
A4: Stock-based Compensation | B4: 10833 | C4: 11688 | D4: 12650
A5: Deferred Income Taxes | B5: -5774 | C5: 4311 | D5: -2228
A6: Changes in Working Capital | B6: 1667 | C6: -4089 | D6: -5369
A7: Other Operating Activities | B7: 1337 | C7: 1163 | D7: 2800
A8: Cash from Operating Activities | B8: 110543 | C8: 118254 | D8: 111482
A9: Capital Expenditures (CapEx) | B9: -10959 | C9: -9447 | D9: -10657
A10: Acquisitions | B10: -1683 | C10: -624 | D10: -780
A11: Purchase of Investments | B11: -29513 | C11: -34095 | D11: -36890
A12: Sale of Investments | B12: 39686 | C12: 40000 | D12: 42120
A13: Other Investing Activities | B13: 0 | C13: 0 | D13: 0
... A22: Free Cash Flow (FCF) | B22: 99584 | C22: 108807 | D22: 98767

Sheet Financial_Ratios
A1: Metric | B1: FY2023 | C1: FY2024 | D1: FY2025
A2: Gross Margin (%) | B2: 44.1 | C2: 46.2 | D2: 46.9
A3: Operating Margin (%) | B3: 29.8 | C3: 31.5 | D3: 32.6
A4: Net Profit Margin (%) | B4: 25.3 | C4: 24 | D4: 26.9
A5: Return on Assets (ROA) (%) | B5: 27.5 | C5: 25.7 | D5: 31.2
A6: Return on Equity (ROE) (%) | B6: 156.1 | C6: 164.6 | D6: 151.9
A7: Current Ratio | B7: 0.99 | C7: 0.87 | D7: 0.89
A8: Debt-to-Equity Ratio | B8: 1.81 | C8: 1.89 | D8: 1.35
A9: Asset Turnover | B9: 1.09 | C9: 1.07 | D9: 1.16
A10: Inventory Turnover | B10: 33.8 | C10: 32.3 | D10: 30.3
A11: Price-to-Earnings (P/E) Ratio | B11: 28.5 | C11: 29.2 | D11: 36.5
A12: Enterprise Value (EV) in billions | B12: 2850 | C12: 2920 | D12: 3150
A13: EV/EBITDA | B13: 23.8 | C13: 24.5 | D13: 26.2
A14: EV/FCF | B14: 28.6 | C14: 26.8 | D14: 31.8

Sheet Stock_Market_Data
A1: Metric | B1: FY2023 | C1: FY2024 | D1: FY2025
A2: Stock Price (end of FY, $) | B2: 171.21 | C2: 226.5 | D2: 273.85
A3: 52-Week High ($) | B3: 198.23 | C3: 237.23 | D3: 285.6
A4: 52-Week Low ($) | B4: 124.17 | C4: 164.08 | D4: 209.27
A5: Market Capitalization (billions) | B5: 2720 | C5: 3440 | D5: 4107
A6: Shares Outstanding (millions) | B6: 15812 | C6: 15204 | D6: 14998
A7: Dividend per Share ($) | B7: 0.96 | C7: 1 | D7: 1.03
A8: Dividend Yield (%) | B8: 0.56 | C8: 0.44 | D8: 0.38
A9: Beta | B9: 1.28 | C9: 1.24 | D9: 1.2

Sheet Model_Assumptions
A1: Assumption | B1: Historical_Avg | C1: Forecast_2026 | D1: Forecast_2027 | E1: Forecast_2028
A2: Revenue Growth Rate (%) | B2: 4.3 | C2: 5 | D2: 4.5 | E2: 4
A3: Gross Margin (%) | B3: 45.7 | C3: 47 | D3: 47.5 | E3: 48
A4: R&D as % of Revenue (%) | B4: 7.9 | C4: 7.8 | D4: 7.7 | E4: 7.6
A5: SG&A as % of Revenue (%) | B5: 6.4 | C5: 6.5 | D5: 6.4 | E5: 6.3
A6: Tax Rate (%) | B6: 21.2 | C6: 18 | D6: 18 | E6: 18
A7: CapEx as % of Revenue (%) | B7: 2.6 | C7: 2.6 | D7: 2.6 | E7: 2.6
A8: Depreciation as % of Revenue (%) | B8: 2.8 | C8: 2.8 | D8: 2.8 | E8: 2.8
A9: Working Capital as % of Revenue (%) | B9: 3.5 | C9: 3.5 | D9: 3.5 | E9: 3.5
A10: Terminal Growth Rate (%) | B10: 3 | C10: 3 | D10: 3 | E10: 3
A11: WACC / Discount Rate (%) | B11: 9.5 | C11: 9 | D11: 9 | E11: 9

Sheet Financial_Analysis
A1: FINANCIAL ANALYSIS
A2: Historical Financial Performance & Key Metrics
A3: Metric | B3: FY2023 | C3: FY2024 | D3: FY2025 | E3: 3-Year Trend
A5: INCOME STATEMENT ANALYSIS
A6: Revenue ($m) | B6: =Income_Statement!B2 -> 383285 | C6: =Income_Statement!C2 -> 391035 | D6: =Income_Statement!D2 -> 416161 | E6: =(D6/B6)^(1/2)-1 -> 0.042004939
A7: Revenue Growth (%) | B7: ="" | C7: =C6/B6-1 -> 0.020219941 | D7: =D6/C6-1 -> 0.064255118 | E7: =AVERAGE(C7:D7) -> 0.042237529
A8: Gross Profit ($m) | B8: =Income_Statement!B4 -> 169148 | C8: =Income_Statement!C4 -> 180683 | D8: =Income_Statement!D4 -> 195201 | E8: =(D8/B8)^(1/2)-1 -> 0.074255499
A9: Gross Margin (%) | B9: =Financial_Ratios!B2/100 -> 0.441 | C9: =Financial_Ratios!C2/100 -> 0.462 | D9: =Financial_Ratios!D2/100 -> 0.469 | E9: =D9-B9 -> 0.028
A10: Operating Income ($m) | B10: =Income_Statement!B8 -> 114301 | C10: =Income_Statement!C8 -> 123216 | D10: =Income_Statement!D8 -> 135793 | E10: =(D10/B10)^(1/2)-1 -> 0.089967821
A11: Operating Margin (%) | B11: =Financial_Ratios!B3/100 -> 0.298 | C11: =Financial_Ratios!C3/100 -> 0.315 | D11: =Financial_Ratios!D3/100 -> 0.326 | E11: =D11-B11 -> 0.028
A12: Net Income ($m) | B12: =Income_Statement!B14 -> 96995 | C12: =Income_Statement!C14 -> 93736 | D12: =Income_Statement!D14 -> 112010 | E12: =(D12/B12)^(1/2)-1 -> 0.074617045
A13: Net Profit Margin (%) | B13: =Financial_Ratios!B4/100 -> 0.253 | C13: =Financial_Ratios!C4/100 -> 0.24 | D13: =Financial_Ratios!D4/100 -> 0.269 | E13: =D13-B13 -> 0.016
A14: Diluted EPS ($) | B14: =Income_Statement!B16 -> 6.16 | C14: =Income_Statement!C16 -> 6.16 | D14: =Income_Statement!D16 -> 7.46 | E14: =(D14/B14)^(1/2)-1 -> 0.10047215
A16: RETURN & OPERATING EFFICIENCY
A17: ROA (%) | B17: =Financial_Ratios!B5/100 -> 0.275 | C17: =Financial_Ratios!C5/100 -> 0.257 | D17: =Financial_Ratios!D5/100 -> 0.312 | E17: =D17-B17 -> 0.037
A18: ROE (%) | B18: =Financial_Ratios!B6/100 -> 1.561 | C18: =Financial_Ratios!C6/100 -> 1.646 | D18: =Financial_Ratios!D6/100 -> 1.519 | E18: =D18-B18 -> -0.042
A19: Asset Turnover | B19: =Financial_Ratios!B9 -> 1.09 | C19: =Financial_Ratios!C9 -> 1.07 | D19: =Financial_Ratios!D9 -> 1.16 | E19: =D19-B19 -> 0.07
A20: Inventory Turnover | B20: =Financial_Ratios!B10 -> 33.8 | C20: =Financial_Ratios!C10 -> 32.3 | D20: =Financial_Ratios!D10 -> 30.3 | E20: =D20-B20 -> -3.5
A21: EPS Growth (%) | C21: =C14/B14-1 -> 0 | D21: =D14/C14-1 -> 0.21103896 | E21: =AVERAGE(C21:D21) -> 0.10551948
A22: Diluted Shares (m) | B22: =Income_Statement!B15 -> 15812 | C22: =Income_Statement!C15 -> 15204 | D22: =Income_Statement!D15 -> 14998 | E22: =(D22/B22)^(1/2)-1 -> -0.026080028
A23: Shares Change (%) | C23: =C22/B22-1 -> -0.038451809 | D23: =D22/C22-1 -> -0.013549066 | E23: =D22/B22-1 -> -0.051479889
A25: LIQUIDITY & LEVERAGE ANALYSIS
A26: Current Ratio | B26: =Financial_Ratios!B7 -> 0.99 | C26: =Financial_Ratios!C7 -> 0.87 | D26: =Financial_Ratios!D7 -> 0.89 | E26: =D26-B26 -> -0.1
A27: Debt-to-Equity | B27: =Financial_Ratios!B8 -> 1.81 | C27: =Financial_Ratios!C8 -> 1.89 | D27: =Financial_Ratios!D8 -> 1.35 | E27: =D27-B27 -> -0.46
A28: Total Debt ($m) | B28: =Balance_Sheet!B16+Balance_Sheet!B19 -> 105103 | C28: =Balance_Sheet!C16+Balance_Sheet!C19 -> 95572 | D28: =Balance_Sheet!D16+Balance_Sheet!D19 -> 86656 | E28: =(D28/B28)^(1/2)-1 -> -0.091987634
A29: Cash & Investments ($m) | B29: =Balance_Sheet!B2+Balance_Sheet!B3 -> 61555 | C29: =Balance_Sheet!C2+Balance_Sheet!C3 -> 65171 | D29: =Balance_Sheet!D2+Balance_Sheet!D3 -> 74084 | E29: =(D29/B29)^(1/2)-1 -> 0.097060412
A30: Net Debt ($m) | B30: =B28-B29 -> 43548 | C30: =C28-C29 -> 30401 | D30: =D28-D29 -> 12572 | E30: =(D30/B30)^(1/2)-1 -> -0.46269847
A31: Total Assets ($m) | B31: =Balance_Sheet!B14 -> 352583 | C31: =Balance_Sheet!C14 -> 364980 | D31: =Balance_Sheet!D14 -> 359241 | E31: =(D31/B31)^(1/2)-1 -> 0.0093975911
A32: Total Liabilities ($m) | B32: =Balance_Sheet!B23 -> 290437 | C32: =Balance_Sheet!C23 -> 308030 | D32: =Balance_Sheet!D23 -> 285508 | E32: =(D32/B32)^(1/2)-1 -> -0.0085217996
A33: Shareholders' Equity ($m) | B33: =Balance_Sheet!B24+Balance_Sheet!B25 -> 73598 | C33: =Balance_Sheet!C24+Balance_Sheet!C25 -> 56846 | D33: =Balance_Sheet!D24+Balance_Sheet!D25 -> 88233 | E33: =(D33/B33)^(1/2)-1 -> 0.094920322
A35: CASH FLOW ANALYSIS
A36: Operating Cash Flow ($m) | B36: =Cash_Flow!B8 -> 110543 | C36: =Cash_Flow!C8 -> 118254 | D36: =Cash_Flow!D8 -> 111482 | E36: =(D36/B36)^(1/2)-1 -> 0.0042382347
A37: Capital Expenditures ($m) | B37: =-Cash_Flow!B9 -> 10959 | C37: =-Cash_Flow!C9 -> 9447 | D37: =-Cash_Flow!D9 -> 10657 | E37: =(D37/B37)^(1/2)-1 -> -0.013874886
A38: Free Cash Flow ($m | B38: =Cash_Flow!B22 -> 99584 | C38: =Cash_Flow!C22 -> 108807 | D38: =Cash_Flow!D22 -> 98767 | E38: =Cash_Flow!E22 -> 0
A39: FCF Margin (%) | B39: =B38/B6 -> 0.25981711 | C39: =C38/C6 -> 0.27825386 | D39: =D38/D6 -> 0.23732882 | E39: =D39-B39 -> -0.022488285
A40: FCF Conversion (%) | B40: =B38/B12 -> 1.0266921 | C40: =C38/C12 -> 1.1607813 | D40: =D38/D12 -> 0.88176948 | E40: =D40-B40 -> -0.14492261
A41: Dividends Paid ($m) | B41: =-Cash_Flow!B19 -> 6012 | C41: =-Cash_Flow!C19 -> 5802 | D41: =-Cash_Flow!D19 -> 6071 | E41: =(D41/B41)^(1/2)-1 -> 0.0048948731
A42: Share Repurchases ($m) | B42: =-Cash_Flow!B18 -> 15025 | C42: =-Cash_Flow!C18 -> 15234 | D42: =-Cash_Flow!D18 -> 15421 | E42: =(D42/B42)^(1/2)-1 -> 0.013092332
A43: Net Change in Cash ($m) | B43: =Cash_Flow!B21 -> 5760 | C43: =Cash_Flow!C21 -> -794 | D43: =Cash_Flow!D21 -> 5991 | E43: =(D43/B43)^(1/2)-1 -> 0.019854973
A45: MARKET & VALUATION ANALYSIS
...

Sheet Forecast
A1: FINANCIAL FORECAST MODEL
A2: Historical Actual & FY2026–FY2028 Forecast
A3: Metric | B3: FY2025A | C3: FY2026E | D3: FY2027E | E3: FY2028E
A5: REVENUE FORECAST
A6: Revenue Growth (%) | B6: =0 -> 0 | C6: =Model_Assumptions!C2 -> 5 | D6: =Model_Assumptions!D2 -> 4.5 | E6: =Model_Assumptions!E2 -> 4
A7: Revenue ($m) | B7: =Income_Statement!D2 -> 416161 | C7: =B7*(1+C6) -> 2496966 | D7: =C7*(1+D6) -> 13733313 | E7: =D7*(1+E6) -> 68666565
A9: GROSS PROFIT FORECAST
A10: Gross Margin (%) | B10: =Income_Statement!D4/Income_Statement!D2 -> 0.46905164 | C10: =Model_Assumptions!C3 -> 47 | D10: =Model_Assumptions!D3 -> 47.5 | E10: =Model_Assumptions!E3 -> 48
A11: Gross Profit ($m) | B11: =Income_Statement!D4 -> 195201 | C11: =C7*C10 -> 117357402 | D11: =D7*D10 -> 6.5233237e+08 | E11: =E7*E10 -> 3295995120
A12: Cost of Revenue ($m) | B12: =B7-B11 -> 220960 | C12: =C7-C11 -> -114860436 | D12: =D7-D11 -> -6.3859905e+08 | E12: =E7-E11 -> -3227328555
A14: OPERATING EXPENSES
A15: R&D as % of Revenue | B15: =Income_Statement!D5/Income_Statement!D2 -> 0.077099969 | C15: =Model_Assumptions!C4 -> 7.8 | D15: =Model_Assumptions!D4 -> 7.7 | E15: =Model_Assumptions!E4 -> 7.6
A16: R&D Expense ($m) | B16: =Income_Statement!D5 -> 32086 | C16: =C7*C15 -> 19476335 | D16: =D7*D15 -> 1.0574651e+08 | E16: =E7*E15 -> 521865894
A18: SG&A as % of Revenue | B18: =Income_Statement!D6/Income_Statement!D2 -> 0.065652476 | C18: =Model_Assumptions!C5 -> 6.5 | D18: =Model_Assumptions!D5 -> 6.4 | E18: =Model_Assumptions!E5 -> 6.3
A19: SG&A Expense ($m) | B19: =Income_Statement!D6 -> 27322 | C19: =C7*C18 -> 16230279 | D19: =D7*D18 -> 87893203 | E19: =E7*E18 -> 4.3259936e+08
A21: OPERATING PROFITABILITY
A22: Total Operating Expenses ($m) | B22: =B16+B19 -> 59408 | C22: =C16+C19 -> 35706614 | D22: =C16+C19 -> 35706614 | E22: =E16+E19 -> 9.5446525e+08
A23: Operating Income ($m) | B23: =B11-B22 -> 135793 | C23: =C11-C22 -> 81650788 | D23: =D11-D22 -> 6.1662575e+08 | E23: =E11-E22 -> 2.3415299e+09
A24: Operating Margin (%) | B24: =B23/B7 -> 0.3262992 | C24: =C23/C7 -> 32.7 | D24: =D23/D7 -> 44.9 | E24: =E23/E7 -> 34.1
A26: PRE-TAX INCOME
A27: Interest Expense ($m) | B27: =Income_Statement!D9 -> 3933 | C27: =B27 -> 3933 | D27: =C27 -> 3933 | E27: =D27 -> 3933
A28: Interest Income ($m) | B28: =Income_Statement!D10 -> 3750 | C28: =B28 -> 3750 | D28: =C28 -> 3750 | E28: =D28 -> 3750
A29: Income Before Tax ($m) | B29: =B23-B27+B28 -> 135610 | C29: =C23-C27+C28 -> 81650605 | D29: =D23-D27+D28 -> 6.1662557e+08 | E29: =E23-E27+E28 -> 2.3415297e+09
A31: NET INCOME FORECAST
A32: Tax Rate (%) | B32: =Income_Statement!D13/Income_Statement!D12 -> 0.18037465 | C32: =Model_Assumptions!C6 -> 18 | D32: =Model_Assumptions!D6 -> 18 | E32: =Model_Assumptions!E6 -> 18
A33: Income Tax ($m) | B33: =Income_Statement!D13 -> 24650 | C33: =C29*C32 -> 1.4697109e+09 | D33: =D29*D32 -> 1.109926e+10 | E33: =E29*E32 -> 42147534303
A34: Net Income ($m) | B34: =Income_Statement!D14 -> 112010 | C34: =C29-C33 -> -1.3880603e+09 | D34: =D29-D33 -> -1.0482635e+10 | E34: =E29-E33 -> -3.9806005e+10
A35: Net Profit Margin (%) | B35: =B34/B7 -> 0.26915064 | C35: =C34/C7 -> -555.89875 | D35: =D34/D7 -> -763.29977 | E35: =E34/E7 -> -579.69995
A37: FREE CASH FLOW FORECAST
A38: Net Income ($m) | B38: =B34 -> 112010 | C38: =C34 -> -1.3880603e+09 | D38: =D34 -> -1.0482635e+10 | E38: =E34 -> -3.9806005e+10
A39: Depreciation & Amortization ($m) | B39: =Cash_Flow!D3 -> 11619 | C39: =C7*Model_Assumptions!C8 -> 6991504.8 | D39: =D7*Model_Assumptions!D8 -> 38453276 | E39: =E7*Model_Assumptions!E8 -> 192266382
A40: Change in Working Capital ($m) | B40: =Cash_Flow!D6 -> -5369 | C40: =C7*Model_Assumptions!C9 -> 8739381 | D40: =D7*Model_Assumptions!D9 -> 48066596 | E40: =E7*Model_Assumptions!E9 -> 2.4033298e+08
A41: Operating Cash Flow ($m) | B41: =B38+B39-B40 -> 128998 | C41: =C38+C39-C40 -> -1.3898082e+09 | D41: =D38+D39-D40 -> -10492248021 | E41: =E38+E39-E40 -> -39854071215
A42: Capital Expenditures ($m) | B42: =-Cash_Flow!D9 -> 10657 | C42: =C7*Model_Assumptions!C7 -> 6492111.6 | D42: =D7*Model_Assumptions!D7 -> 35706614 | E42: =E7*Model_Assumptions!E7 -> 178533069
A43: Free Cash Flow ($m) | B43: =B41-B42 -> 118341 | C43: =C41-C42 -> -1.3963003e+09 | D43: =D41-D42 -> -1.0527955e+10 | E43: =E41-E42 -> -40032604284
A44: FCF Margin (%) | B44: =B43/B7 -> 0.2843635 | C44: =C43/C7 -> -559.19875 | D44: =D43/D7 -> -766.59977 | E44: =E43/E7 -> -582.99995
A46: FORECAST SUMMARY
A47: Revenue ($m) | B47: =B7 -> 416161 | C47: =C7 -> 2496966 | D47: =D7 -> 13733313 | E47: =E7 -> 68666565
A48: Operating Income ($m) | B48: =B23 -> 135793 | C48: =C23 -> 81650788 | D48: =D23 -> 6.1662575e+08 | E48: =E23 -> 2.3415299e+09
A49: Net Income ($m) | B49: =B34 -> 112010 | C49: =C34 -> -1.3880603e+09 | D49: =D34 -> -1.0482635e+10 | E49: =E34 -> -3.9806005e+10
...

Sheet DCF_Valuation
A1: DCF VALUATION
A2: Discounted Cash Flow Valuation Model
A3: Metric | B3: FY2026E | C3: FY2027E | D3: FY2028E | E3: Terminal
A5: DCF ASSUMPTIONS
A6: WACC / Discount Rate | B6: =Model_Assumptions!C11/100 -> 0.09
A7: Terminal Growth Rate | B7: =Model_Assumptions!C10/100 -> 0.03
A8: FY2025 Net Debt ($m) | B8: =Balance_Sheet!D16+Balance_Sheet!D19-Balance_Sheet!D2-Balance_Sheet!D3 -> 12572
A9: Shares Outstanding (million) | B9: =Stock_Market_Data!D5 -> 4107
A10: Current Stock Price ($) | B10: =Stock_Market_Data!D2 -> 273.85
A12: FREE CASH FLOW PROJECTION
A13: Free Cash Flow ($m) | B13: =Forecast!C43 -> -1.3963003e+09 | C13: =Forecast!D43 -> -1.0527955e+10 | D13: =Forecast!E43 -> -40032604284 | E13: =D13*(1+$B$7) -> -4.1233582e+10
A14: Growth Rate | B14: =Forecast!C6 -> 5 | C14: =Forecast!D6 -> 4.5 | D14: =Forecast!E6 -> 4 | E14: =$B$7 -> 0.03
A16: DISCOUNTING
A17: Discount Period | B17: =1 -> 1 | C17: =2 -> 2 | D17: =3 -> 3 | E17: =3 -> 3
A18: Discount Factor | B18: =1/(1+$B$6)^B17 -> 0.91743119 | C18: =1/(1+$B$6)^C17 -> 0.84167999 | D18: =1/(1+$B$6)^D17 -> 0.77218348 | E18: =1/(1+$B$6)^E17 -> 0.77218348
A20: PRESENT VALUE OF CASH FLOWS
A21: Free Cash Flow ($m) | B21: =B13 -> -1.3963003e+09 | C21: =C13 -> -1.0527955e+10 | D21: =D13 -> -40032604284 | E21: =E13 -> -4.1233582e+10
A22: Present Value of FCF ($m) | B22: =B21*B18 -> -1.2810094e+09 | C22: =C21*C18 -> -8.8611688e+09 | D22: =D21*D18 -> -3.0912516e+10
A24: TERMINAL VALUE
A25: Terminal Year FCF ($m) | B25: =E13 -> -4.1233582e+10
A26: Terminal Growth Rate | B26: =$B$7 -> 0.03
A27: Terminal Value ($m) | B27: =B25*(1+B26)/($B$6-B26) -> -7.0784316e+11
A29: PV OF TERMINAL VALUE
A30: Terminal Value ($m) | B30: =B27 -> -7.0784316e+11
A31: Terminal Discount Factor | B31: =E18 -> 0.77218348
A32: Present Value of Terminal Value ($m) | B32: =B30*B31 -> -5.465848e+11
A34: ENTERPRISE VALUE
A35: PV of FY2026 FCF | B35: =B22 -> -1.2810094e+09
A36: PV of FY2027 FCF | B36: =C22 -> -8.8611688e+09
A37: PV of FY2028 FCF | B37: =D22 -> -3.0912516e+10
A38: PV of Terminal Value | B38: =B32 -> -5.465848e+11
A39: Enterprise Value ($m) | B39: =SUM(B35:B38) -> -5.8763949e+11
A41: EQUITY VALUE
A42: Enterprise Value ($m) | B42: =B39 -> -5.8763949e+11
A43: Less: Net Debt ($m) | B43: =B8 -> 12572
A44: Equity Value ($m) | B44: =B42-B43 -> -5.876395e+11
A45: Shares Outstanding (million) | B45: =B9 -> 4107
A47: INTRINSIC VALUE
A48: DCF Equity Value ($m) | B48: =B44 -> -5.876395e+11
A49: Shares Outstanding (million) | B49: =B45 -> 4107
...

Sheet Sensitivity
A1: DCF SENSITIVITY ANALYSIS
A2: Intrinsic Value per Share under Different WACC & Terminal Growth Scenarios
A4: Base WACC | B4: =DCF_Valuation!B6 -> 0.09
A5: Base Terminal Growth | B5: =DCF_Valuation!B7 -> 0.03
A6: Base Intrinsic Value / Share | B6: =DCF_Valuation!B50 -> -1.4308242e+08
A7: Current Market Price | B7: =DCF_Valuation!B51 -> 273.85
A10: DCF INTRINSIC VALUE PER SHARE
A11: WACC / Terminal Growth | B11: 0.02 | C11: 0.025 | D11: 0.03 | E11: 0.035 | F11: 0.04
A12: 0.08 | B12: =( SUMPRODUCT(DCF_Valuation!$B$13:$D$13,1/(1+$A12)^DCF_Valuation!$B$17:$D$17) + (DCF_Valuation!$D$13*(1+B$11)/($A12-B$11))/(1+$A12)^DCF_Valuation!$E$17 -DCF_Valuation!$B$8 )/DCF_Valuation!$B$9 -> -1.4179304e+08 | C12: =( SUMPRODUCT(DCF_Valuation!$B$13:$D$13,1/(1+$A12)^DCF_Valuation!$B$17:$D$17) + (DCF_Valuation!$D$13*(1+C$11)/($A12-C$11))/(1+$A12)^DCF_Valuation!$E$17 -DCF_Valuation!$B$8 )/DCF_Valuation!$B$9 -> -1.544549e+08 | D12: =( SUMPRODUCT(DCF_Valuation!$B$13:$D$13,1/(1+$A12)^DCF_Valuation!$B$17:$D$17) + (DCF_Valuation!$D$13*(1+D$11)/($A12-D$11))/(1+$A12)^DCF_Valuation!$E$17 -DCF_Valuation!$B$8 )/DCF_Valuation!$B$9 -> -1.6964914e+08 | E12: =( SUMPRODUCT(DCF_Valuation!$B$13:$D$13,1/(1+$A12)^DCF_Valuation!$B$17:$D$17) + (DCF_Valuation!$D$13*(1+E$11)/($A12-E$11))/(1+$A12)^DCF_Valuation!$E$17 -DCF_Valuation!$B$8 )/DCF_Valuation!$B$9 -> -1.8821988e+08 | F12: =( SUMPRODUCT(DCF_Valuation!$B$13:$D$13,1/(1+$A12)^DCF_Valuation!$B$17:$D$17) + (DCF_Valuation!$D$13*(1+F$11)/($A12-F$11))/(1+$A12)^DCF_Valuation!$E$17 -DCF_Valuation!$B$8 )/DCF_Valuation!$B$9 -> -2.114333e+08
A13: 0.085 | B13: =( SUMPRODUCT(DCF_Valuation!$B$13:$D$13,1/(1+$A13)^DCF_Valuation!$B$17:$D$17) + (DCF_Valuation!$D$13*(1+B$11)/($A13-B$11))/(1+$A13)^DCF_Valuation!$E$17 -DCF_Valuation!$B$8 )/DCF_Valuation!$B$9 -> -1.2987528e+08 | C13: =( SUMPRODUCT(DCF_Valuation!$B$13:$D$13,1/(1+$A13)^DCF_Valuation!$B$17:$D$17) + (DCF_Valuation!$D$13*(1+C$11)/($A13-C$11))/(1+$A13)^DCF_Valuation!$E$17 -DCF_Valuation!$B$8 )/DCF_Valuation!$B$9 -> -1.4049064e+08 | D13: =( SUMPRODUCT(DCF_Valuation!$B$13:$D$13,1/(1+$A13)^DCF_Valuation!$B$17:$D$17) + (DCF_Valuation!$D$13*(1+D$11)/($A13-D$11))/(1+$A13)^DCF_Valuation!$E$17 -DCF_Valuation!$B$8 )/DCF_Valuation!$B$9 -> -1.5303608e+08 | E13: =( SUMPRODUCT(DCF_Valuation!$B$13:$D$13,1/(1+$A13)^DCF_Valuation!$B$17:$D$17) + (DCF_Valuation!$D$13*(1+E$11)/($A13-E$11))/(1+$A13)^DCF_Valuation!$E$17 -DCF_Valuation!$B$8 )/DCF_Valuation!$B$9 -> -1.680906e+08 | F13: =( SUMPRODUCT(DCF_Valuation!$B$13:$D$13,1/(1+$A13)^DCF_Valuation!$B$17:$D$17) + (DCF_Valuation!$D$13*(1+F$11)/($A13-F$11))/(1+$A13)^DCF_Valuation!$E$17 -DCF_Valuation!$B$8 )/DCF_Valuation!$B$9 -> -1.8649057e+08
A14: 0.09 | B14: =( SUMPRODUCT(DCF_Valuation!$B$13:$D$13,1/(1+$A14)^DCF_Valuation!$B$17:$D$17) + (DCF_Valuation!$D$13*(1+B$11)/($A14-B$11))/(1+$A14)^DCF_Valuation!$E$17 -DCF_Valuation!$B$8 )/DCF_Valuation!$B$9 -> -1.1967232e+08 | C14: =( SUMPRODUCT(DCF_Valuation!$B$13:$D$13,1/(1+$A14)^DCF_Valuation!$B$17:$D$17) + (DCF_Valuation!$D$13*(1+C$11)/($A14-C$11))/(1+$A14)^DCF_Valuation!$E$17 -DCF_Valuation!$B$8 )/DCF_Valuation!$B$9 -> -1.2868792e+08 | D14: =( SUMPRODUCT(DCF_Valuation!$B$13:$D$13,1/(1+$A14)^DCF_Valuation!$B$17:$D$17) + (DCF_Valuation!$D$13*(1+D$11)/($A14-D$11))/(1+$A14)^DCF_Valuation!$E$17 -DCF_Valuation!$B$8 )/DCF_Valuation!$B$9 -> -1.3920613e+08 | E14: =( SUMPRODUCT(DCF_Valuation!$B$13:$D$13,1/(1+$A14)^DCF_Valuation!$B$17:$D$17) + (DCF_Valuation!$D$13*(1+E$11)/($A14-E$11))/(1+$A14)^DCF_Valuation!$E$17 -DCF_Valuation!$B$8 )/DCF_Valuation!$B$9 -> -1.5163673e+08 | F14: =( SUMPRODUCT(DCF_Valuation!$B$13:$D$13,1/(1+$A14)^DCF_Valuation!$B$17:$D$17) + (DCF_Valuation!$D$13*(1+F$11)/($A14-F$11))/(1+$A14)^DCF_Valuation!$E$17 -DCF_Valuation!$B$8 )/DCF_Valuation!$B$9 -> -1.6655345e+08
A15: 0.095 | B15: =( SUMPRODUCT(DCF_Valuation!$B$13:$D$13,1/(1+$A15)^DCF_Valuation!$B$17:$D$17) + (DCF_Valuation!$D$13*(1+B$11)/($A15-B$11))/(1+$A15)^DCF_Valuation!$E$17 -DCF_Valuation!$B$8 )/DCF_Valuation!$B$9 -> -1.1084101e+08 | C15: =( SUMPRODUCT(DCF_Valuation!$B$13:$D$13,1/(1+$A15)^DCF_Valuation!$B$17:$D$17) + (DCF_Valuation!$D$13*(1+C$11)/($A15-C$11))/(1+$A15)^DCF_Valuation!$E$17 -DCF_Valuation!$B$8 )/DCF_Valuation!$B$9 -> -1.1858334e+08 | D15: =( SUMPRODUCT(DCF_Valuation!$B$13:$D$13,1/(1+$A15)^DCF_Valuation!$B$17:$D$17) + (DCF_Valuation!$D$13*(1+D$11)/($A15-D$11))/(1+$A15)^DCF_Valuation!$E$17 -DCF_Valuation!$B$8 )/DCF_Valuation!$B$9 -> -1.2751679e+08 | E15: =( SUMPRODUCT(DCF_Valuation!$B$13:$D$13,1/(1+$A15)^DCF_Valuation!$B$17:$D$17) + (DCF_Valuation!$D$13*(1+E$11)/($A15-E$11))/(1+$A15)^DCF_Valuation!$E$17 -DCF_Valuation!$B$8 )/DCF_Valuation!$B$9 -> -1.3793916e+08 | F15: =( SUMPRODUCT(DCF_Valuation!$B$13:$D$13,1/(1+$A15)^DCF_Valuation!$B$17:$D$17) + (DCF_Valuation!$D$13*(1+F$11)/($A15-F$11))/(1+$A15)^DCF_Valuation!$E$17 -DCF_Valuation!$B$8 )/DCF_Valuation!$B$9 -> -1.502565e+08
A16: 0.1 | B16: =( SUMPRODUCT(DCF_Valuation!$B$13:$D$13,1/(1+$A16)^DCF_Valuation!$B$17:$D$17) + (DCF_Valuation!$D$13*(1+B$11)/($A16-B$11))/(1+$A16)^DCF_Valuation!$E$17 -DCF_Valuation!$B$8 )/DCF_Valuation!$B$9 -> -1.0312397e+08 | C16: =( SUMPRODUCT(DCF_Valuation!$B$13:$D$13,1/(1+$A16)^DCF_Valuation!$B$17:$D$17) + (DCF_Valuation!$D$13*(1+C$11)/($A16-C$11))/(1+$A16)^DCF_Valuation!$E$17 -DCF_Valuation!$B$8 )/DCF_Valuation!$B$9 -> -1.0983706e+08 | D16: =( SUMPRODUCT(DCF_Valuation!$B$13:$D$13,1/(1+$A16)^DCF_Valuation!$B$17:$D$17) + (DCF_Valuation!$D$13*(1+D$11)/($A16-D$11))/(1+$A16)^DCF_Valuation!$E$17 -DCF_Valuation!$B$8 )/DCF_Valuation!$B$9 -> -1.1750916e+08 | E16: =( SUMPRODUCT(DCF_Valuation!$B$13:$D$13,1/(1+$A16)^DCF_Valuation!$B$17:$D$17) + (DCF_Valuation!$D$13*(1+E$11)/($A16-E$11))/(1+$A16)^DCF_Valuation!$E$17 -DCF_Valuation!$B$8 )/DCF_Valuation!$B$9 -> -1.2636159e+08 | F16: =( SUMPRODUCT(DCF_Valuation!$B$13:$D$13,1/(1+$A16)^DCF_Valuation!$B$17:$D$17) + (DCF_Valuation!$D$13*(1+F$11)/($A16-F$11))/(1+$A16)^DCF_Valuation!$E$17 -DCF_Valuation!$B$8 )/DCF_Valuation!$B$9 -> -1.3668942e+08
A19: IMPLIED UPSIDE / (DOWNSIDE)
A20: WACC / Terminal Growth | B20: 0.02 | C20: 0.025 | D20: 0.03 | E20: 0.035 | F20: 0.04
A21: 0.08 | B21: =(B12/$B$7)-1 -> -517777.29 | C21: =(C12/$B$7)-1 -> -564013.79 | D21: =(D12/$B$7)-1 -> -619497.59 | E21: =(E12/$B$7)-1 -> -687311.12 | F21: =(F12/$B$7)-1 -> -772078.04
A22: 0.085 | B22: =(B13/$B$7)-1 -> -474257.99 | C22: =(C13/$B$7)-1 -> -513021.43 | D22: =(D13/$B$7)-1 -> -558832.77 | E22: =(E13/$B$7)-1 -> -613806.37 | F22: =(F13/$B$7)-1 -> -680996.34
A23: 0.09 | B23: =(B14/$B$7)-1 -> -437000.53 | C23: =(C14/$B$7)-1 -> -469922.21 | D23: =(D14/$B$7)-1 -> -508330.84 | E23: =(E14/$B$7)-1 -> -553722.85 | F23: =(F14/$B$7)-1 -> -608193.27
A24: 0.095 | B24: =(B15/$B$7)-1 -> -404751.8 | C24: =(C15/$B$7)-1 -> -433023.95 | D24: =(D15/$B$7)-1 -> -465645.67 | E24: =(E15/$B$7)-1 -> -503704.33 | F24: =(F15/$B$7)-1 -> -548682.75
A25: 0.1 | B25: =(B16/$B$7)-1 -> -376571.99 | C25: =(C16/$B$7)-1 -> -401085.74 | D25: =(D16/$B$7)-1 -> -429101.46 | E25: =(E16/$B$7)-1 -> -461427.28 | F25: =(F16/$B$7)-1 -> -499140.75
A28: KEY SENSITIVITY OBSERVATIONS
A29: 1. Higher WACC reduces the present value of future cash flows.
A30: 2. Higher terminal growth increases the terminal value and intrinsic value.
A31: 3. The 9.0% WACC and 3.0% terminal growth scenario represents the base case.
A32: 4. The sensitivity table shows how valuation changes under different discount-rate and terminal-growth assumptions.

Sheet Summary
A1: APPLE INC. — FINANCIAL MODELING & VALUATION SUMMARY
A2: Historical Performance, Forecast & DCF Valuation
A4: VALUATION SNAPSHOT | D4: HISTORICAL PERFORMANCE
A5: Current Market Price | B5: =DCF_Valuation!B51 -> 273.85 | D5: Metric | E5: FY2023 | F5: FY2024 | G5: FY2025
A6: DCF Intrinsic Value / Share | B6: =DCF_Valuation!B50 -> -1.4308242e+08 | D6: Revenue | E6: =Financial_Analysis!B6 -> 383285 | F6: =Financial_Analysis!C6 -> 391035 | G6: =Financial_Analysis!D6 -> 416161
A7: Implied Upside / (Downside) | B7: =DCF_Valuation!B52 -> -522485.65 | D7: Gross Margin | E7: =Financial_Analysis!B9 -> 0.441 | F7: =Financial_Analysis!C9 -> 0.462 | G7: =Financial_Analysis!D9 -> 0.469
A8: WACC | B8: =DCF_Valuation!B6 -> 0.09 | D8: Operating Income | E8: =Financial_Analysis!B10 -> 114301 | F8: =Financial_Analysis!C10 -> 123216 | G8: =Financial_Analysis!D10 -> 135793
A9: Equity Value | B9: =DCF_Valuation!B44 -> -5.876395e+11 | D9: Operating Margin | E9: =Financial_Analysis!B11 -> 0.298 | F9: =Financial_Analysis!C11 -> 0.315 | G9: =Financial_Analysis!D11 -> 0.326
A10: Terminal Growth | B10: =DCF_Valuation!B7 -> 0.03 | D10: Net Income | E10: =Financial_Analysis!B12 -> 96995 | F10: =Financial_Analysis!C12 -> 93736 | G10: =Financial_Analysis!D12 -> 112010
A11: Enterprise Value | B11: =DCF_Valuation!B39 -> -5.8763949e+11 | D11: Net Margin | E11: =Financial_Analysis!B13 -> 0.253 | F11: =Financial_Analysis!C13 -> 0.24 | G11: =Financial_Analysis!D13 -> 0.269
A12: Net Debt | B12: =DCF_Valuation!B8 -> 12572 | D12: Free Cash Flow | E12: =Financial_Analysis!B38 -> 99584 | F12: =Financial_Analysis!C38 -> 108807 | G12: =Financial_Analysis!D38 -> 98767
D13: Diluted EPS | E13: =Financial_Analysis!B14 -> 6.16 | F13: =Financial_Analysis!C14 -> 6.16 | G13: =Financial_Analysis!D14 -> 7.46
A15: FORECAST SUMMARY | G15: DCF VALUATION
A16: Metric | B16: FY2025A | C16: FY2026E | D16: FY2027E | E16: FY2028E | G16: Metric | H16: Value
A17: Revenue | B17: =Forecast!B7 -> 416161 | C17: =Forecast!C7 -> 2496966 | D17: =Forecast!D7 -> 13733313 | E17: =Forecast!E7 -> 68666565 | G17: PV of Forecast FCF | H17: =SUM(DCF_Valuation!B35:B37) -> -4.1054694e+10
A18: Operating Income | B18: =Forecast!B23 -> 135793 | C18: =Forecast!C23 -> 81650788 | D18: =Forecast!D23 -> 6.1662575e+08 | E18: =Forecast!E23 -> 2.3415299e+09 | G18: PV of Terminal Value | H18: =DCF_Valuation!B38 -> -5.465848e+11
A19: Operating Margin % | B19: =Forecast!B24 -> 0.3262992 | C19: =Forecast!C24 -> 32.7 | D19: =Forecast!D24 -> 44.9 | E19: =Forecast!E24 -> 34.1 | G19: Enterprise Value | H19: =DCF_Valuation!B39 -> -5.8763949e+11
A20: Net Income | B20: =Forecast!B34 -> 112010 | C20: =Forecast!C34 -> -1.3880603e+09 | D20: =Forecast!D34 -> -1.0482635e+10 | E20: =Forecast!E34 -> -3.9806005e+10 | G20: Less: Net Debt | H20: =DCF_Valuation!B43 -> 12572
A21: Free Cash Flow | B21: =Forecast!B43 -> 118341 | C21: =Forecast!C43 -> -1.3963003e+09 | D21: =Forecast!D43 -> -1.0527955e+10 | E21: =Forecast!E43 -> -40032604284 | G21: Equity Value | H21: =DCF_Valuation!B44 -> -5.876395e+11
A22: FCF Margin % | B22: =Forecast!B44 -> 0.2843635 | C22: =Forecast!C44 -> -559.19875 | D22: =Forecast!D44 -> -766.59977 | E22: =Forecast!E44 -> -582.99995 | G22: Intrinsic Value / Share | H22: =DCF_Valuation!B50 -> -1.4308242e+08
G23: Current Market Price | H23: =DCF_Valuation!B51 -> 273.85
G24: Implied Upside / (Downside) | H24: =DCF_Valuation!B52 -> -522485.65
A25: KEY MODEL OBSERVATIONS
A26: 1.Historical revenue and net income performance provide the foundation for the forecast period.
A27: 2.The forecast assumes moderate revenue growth with gradual improvement in gross margin. | G27: SENSITIVITY SUMMARY
A28: 3.Free cash flow remains a key driver of the DCF valuation. | G28: Scenario | H28: Intrinsic Value / Share
A29: 4.DCF value is sensitive to changes in WACC and terminal growth assumptions. | G29: 8.0% WACC / 2.0% Growth | H29: =Sensitivity!B12 -> -1.4179304e+08
A30: 5.The base-case valuation uses a 9.0% WACC and 3.0% terminal growth rate. | G30: 8.0% WACC / 4.0% Growth | H30: =Sensitivity!B13 -> -1.2987528e+08
G31: Base Case: 9.0% / 3.0% | H31: =Sensitivity!B14 -> -1.1967232e+08
G32: 10.0% WACC / 2.0% Growth | H32: =Sensitivity!B15 -> -1.1084101e+08
G33: 10.0% WACC / 4.0% Growth | H33: =Sensitivity!B16 -> -1.0312397e+08
